<?xml version="1.0" ?>
<!-- =================================================================================== -->
<!-- |    This document was autogenerated by xacro from urdf\cat.xacro                 | -->
<!-- |    EDITING THIS FILE BY HAND IS NOT RECOMMENDED                                 | -->
<!-- =================================================================================== -->
<robot xmlns:xacro="http://www.ros.org/wiki/xacro" name="cat">
  <material name="silver">
    <color rgba="0.700 0.700 0.700 1.000"/>
  </material>
  <transmission name="tail_tran">
    <type>transmission_interface/SimpleTransmission</type>
    <joint name="tail">
      <hardwareInterface>hardware_interface/EffortJointInterface</hardwareInterface>
    </joint>
    <actuator name="tail_actr">
      <hardwareInterface>hardware_interface/EffortJointInterface</hardwareInterface>
      <mechanicalReduction>1</mechanicalReduction>
    </actuator>
  </transmission>
  <transmission name="leftfront_tran">
    <type>transmission_interface/SimpleTransmission</type>
    <joint name="leftfront">
      <hardwareInterface>hardware_interface/EffortJointInterface</hardwareInterface>
    </joint>
    <actuator name="leftfront_actr">
      <hardwareInterface>hardware_interface/EffortJointInterface</hardwareInterface>
      <mechanicalReduction>1</mechanicalReduction>
    </actuator>
  </transmission>
  <transmission name="leftback_tran">
    <type>transmission_interface/SimpleTransmission</type>
    <joint name="leftback">
      <hardwareInterface>hardware_interface/EffortJointInterface</hardwareInterface>
    </joint>
    <actuator name="leftback_actr">
      <hardwareInterface>hardware_interface/EffortJointInterface</hardwareInterface>
      <mechanicalReduction>1</mechanicalReduction>
    </actuator>
  </transmission>
  <transmission name="rigtfront_tran">
    <type>transmission_interface/SimpleTransmission</type>
    <joint name="rigtfront">
      <hardwareInterface>hardware_interface/EffortJointInterface</hardwareInterface>
    </joint>
    <actuator name="rigtfront_actr">
      <hardwareInterface>hardware_interface/EffortJointInterface</hardwareInterface>
      <mechanicalReduction>1</mechanicalReduction>
    </actuator>
  </transmission>
  <transmission name="rightback_tran">
    <type>transmission_interface/SimpleTransmission</type>
    <joint name="rightback">
      <hardwareInterface>hardware_interface/EffortJointInterface</hardwareInterface>
    </joint>
    <actuator name="rightback_actr">
      <hardwareInterface>hardware_interface/EffortJointInterface</hardwareInterface>
      <mechanicalReduction>1</mechanicalReduction>
    </actuator>
  </transmission>
  <gazebo>
    <plugin name="control" filename="libgazebo_ros_control.so"/>
  </gazebo>
  <gazebo reference="base_link">
    <material>Gazebo/Silver</material>
    <mu1>0.2</mu1>
    <mu2>0.2</mu2>
    <selfCollide>true</selfCollide>
    <gravity>true</gravity>
  </gazebo>
  <gazebo reference="tail_1">
    <material>Gazebo/Silver</material>
    <mu1>0.2</mu1>
    <mu2>0.2</mu2>
    <selfCollide>true</selfCollide>
  </gazebo>
  <gazebo reference="left_front_foot_1">
    <material>Gazebo/Silver</material>
    <mu1>0.2</mu1>
    <mu2>0.2</mu2>
    <selfCollide>true</selfCollide>
  </gazebo>
  <gazebo reference="left_back_foot_1">
    <material>Gazebo/Silver</material>
    <mu1>0.2</mu1>
    <mu2>0.2</mu2>
    <selfCollide>true</selfCollide>
  </gazebo>
  <gazebo reference="right_front_foot_1">
    <material>Gazebo/Silver</material>
    <mu1>0.2</mu1>
    <mu2>0.2</mu2>
    <selfCollide>true</selfCollide>
  </gazebo>
  <gazebo reference="right_back_foot_1">
    <material>Gazebo/Silver</material>
    <mu1>0.2</mu1>
    <mu2>0.2</mu2>
    <selfCollide>true</selfCollide>
  </gazebo>
  <gazebo reference="catHead_1">
    <material>Gazebo/Silver</material>
    <mu1>0.2</mu1>
    <mu2>0.2</mu2>
    <selfCollide>true</selfCollide>
  </gazebo>
  <link name="base_link">
    <inertial>
      <origin xyz="0.011010613939484725 -0.004999999925585087 0.014978417441981655" rpy="0 0 0"/>
      <mass value="0.12612097423673566"/>
      <inertia ixx="8e-06" iyy="2.1e-05" izz="2.1e-05" ixy="0.0" iyz="0.0" ixz="-0.0"/>
    </inertial>
    <visual>
      <origin xyz="0 0 0" rpy="0 0 0"/>
      <geometry>
        <mesh filename="package://cat_description/meshes/base_link.stl" scale="0.001 0.001 0.001"/>
      </geometry>
      <material name="silver"/>
    </visual>
    <collision>
      <origin xyz="0 0 0" rpy="0 0 0"/>
      <geometry>
        <mesh filename="package://cat_description/meshes/base_link.stl" scale="0.001 0.001 0.001"/>
      </geometry>
    </collision>
  </link>
  <link name="tail_1">
    <inertial>
      <origin xyz="0.010279326330687982 -0.005895258029876453 -0.005489326415832978" rpy="0 0 0"/>
      <mass value="0.002782528468533639"/>
      <inertia ixx="0.0" iyy="0.0" izz="0.0" ixy="0.0" iyz="-0.0" ixz="0.0"/>
    </inertial>
    <visual>
      <origin xyz="-0.0315 0.005 -0.02" rpy="0 0 0"/>
      <geometry>
        <mesh filename="package://cat_description/meshes/tail_1.stl" scale="0.001 0.001 0.001"/>
      </geometry>
      <material name="silver"/>
    </visual>
    <collision>
      <origin xyz="-0.0315 0.005 -0.02" rpy="0 0 0"/>
      <geometry>
        <mesh filename="package://cat_description/meshes/tail_1.stl" scale="0.001 0.001 0.001"/>
      </geometry>
    </collision>
  </link>
  <link name="left_front_foot_1">
    <inertial>
      <origin xyz="0.00030643508830082745 -0.001823405580467924 -0.0026808178760243445" rpy="0 0 0"/>
      <mass value="0.001099748300690054"/>
      <inertia ixx="0.0" iyy="0.0" izz="0.0" ixy="0.0" iyz="-0.0" ixz="0.0"/>
    </inertial>
    <visual>
      <origin xyz="0.004 0.0155 -0.008" rpy="0 0 0"/>
      <geometry>
        <mesh filename="package://cat_description/meshes/left_front_foot_1.stl" scale="0.001 0.001 0.001"/>
      </geometry>
      <material name="silver"/>
    </visual>
    <collision>
      <origin xyz="0.004 0.0155 -0.008" rpy="0 0 0"/>
      <geometry>
        <mesh filename="package://cat_description/meshes/left_front_foot_1.stl" scale="0.001 0.001 0.001"/>
      </geometry>
    </collision>
  </link>
  <link name="left_back_foot_1">
    <inertial>
      <origin xyz="0.0022102978015012577 -0.001823405580467924 -0.001547666801972089" rpy="0 0 0"/>
      <mass value="0.001099748300690053"/>
      <inertia ixx="0.0" iyy="0.0" izz="0.0" ixy="0.0" iyz="-0.0" ixz="0.0"/>
    </inertial>
    <visual>
      <origin xyz="-0.025 0.0155 -0.008" rpy="0 0 0"/>
      <geometry>
        <mesh filename="package://cat_description/meshes/left_back_foot_1.stl" scale="0.001 0.001 0.001"/>
      </geometry>
      <material name="silver"/>
    </visual>
    <collision>
      <origin xyz="-0.025 0.0155 -0.008" rpy="0 0 0"/>
      <geometry>
        <mesh filename="package://cat_description/meshes/left_back_foot_1.stl" scale="0.001 0.001 0.001"/>
      </geometry>
    </collision>
  </link>
  <link name="right_front_foot_1">
    <inertial>
      <origin xyz="0.0004446245175916651 0.0018234057294795403 -0.0026613899298190908" rpy="0 0 0"/>
      <mass value="0.0010997483006900198"/>
      <inertia ixx="0.0" iyy="0.0" izz="0.0" ixy="-0.0" iyz="0.0" ixz="0.0"/>
    </inertial>
    <visual>
      <origin xyz="-0.025 -0.0055 -0.008" rpy="0 0 0"/>
      <geometry>
        <mesh filename="package://cat_description/meshes/right_front_foot_1.stl" scale="0.001 0.001 0.001"/>
      </geometry>
      <material name="silver"/>
    </visual>
    <collision>
      <origin xyz="-0.025 -0.0055 -0.008" rpy="0 0 0"/>
      <geometry>
        <mesh filename="package://cat_description/meshes/right_front_foot_1.stl" scale="0.001 0.001 0.001"/>
      </geometry>
    </collision>
  </link>
  <link name="right_back_foot_1">
    <inertial>
      <origin xyz="-0.0026597355422176595 0.0018234057294795403 0.000454417092891745" rpy="0 0 0"/>
      <mass value="0.0010997483006900202"/>
      <inertia ixx="0.0" iyy="0.0" izz="0.0" ixy="0.0" iyz="-0.0" ixz="0.0"/>
    </inertial>
    <visual>
      <origin xyz="0.004 -0.0055 -0.008" rpy="0 0 0"/>
      <geometry>
        <mesh filename="package://cat_description/meshes/right_back_foot_1.stl" scale="0.001 0.001 0.001"/>
      </geometry>
      <material name="silver"/>
    </visual>
    <collision>
      <origin xyz="0.004 -0.0055 -0.008" rpy="0 0 0"/>
      <geometry>
        <mesh filename="package://cat_description/meshes/right_back_foot_1.stl" scale="0.001 0.001 0.001"/>
      </geometry>
    </collision>
  </link>
  <link name="catHead_1">
    <inertial>
      <origin xyz="-0.008364026944009584 6.73987801333431e-11 -1.614121996845741e-05" rpy="0 0 0"/>
      <mass value="0.04158145000236873"/>
      <inertia ixx="2e-06" iyy="2e-06" izz="3e-06" ixy="-0.0" iyz="-0.0" ixz="-0.0"/>
    </inertial>
    <visual>
      <origin xyz="0.009 0.005 -0.015" rpy="0 0 0"/>
      <geometry>
        <mesh filename="package://cat_description/meshes/catHead_1.stl" scale="0.001 0.001 0.001"/>
      </geometry>
      <material name="silver"/>
    </visual>
    <collision>
      <origin xyz="0.009 0.005 -0.015" rpy="0 0 0"/>
      <geometry>
        <mesh filename="package://cat_description/meshes/catHead_1.stl" scale="0.001 0.001 0.001"/>
      </geometry>
    </collision>
  </link>
  <joint name="tail" type="continuous">
    <origin xyz="0.0315 -0.005 0.02" rpy="0 0 0"/>
    <parent link="base_link"/>
    <child link="tail_1"/>
    <axis xyz="1.0 0.0 0.0"/>
  </joint>
  <joint name="leftfront" type="continuous">
    <origin xyz="-0.004 -0.0155 0.008" rpy="0 0 0"/>
    <parent link="base_link"/>
    <child link="left_front_foot_1"/>
    <axis xyz="0.0 -1.0 0.0"/>
  </joint>
  <joint name="leftback" type="continuous">
    <origin xyz="0.025 -0.0155 0.008" rpy="0 0 0"/>
    <parent link="base_link"/>
    <child link="left_back_foot_1"/>
    <axis xyz="0.0 -1.0 0.0"/>
  </joint>
  <joint name="rigtfront" type="continuous">
    <origin xyz="0.025 0.0055 0.008" rpy="0 0 0"/>
    <parent link="base_link"/>
    <child link="right_front_foot_1"/>
    <axis xyz="0.0 1.0 0.0"/>
  </joint>
  <joint name="rightback" type="continuous">
    <origin xyz="-0.004 0.0055 0.008" rpy="0 0 0"/>
    <parent link="base_link"/>
    <child link="right_back_foot_1"/>
    <axis xyz="0.0 1.0 0.0"/>
  </joint>
  <joint name="Rigid 7" type="fixed">
    <origin xyz="-0.009 -0.005 0.015" rpy="0 0 0"/>
    <parent link="base_link"/>
    <child link="catHead_1"/>
  </joint>
</robot>
