<?xml version="1.0" ?>
<robot name="car_v2_copy1019" xmlns:xacro="http://www.ros.org/wiki/xacro">

<xacro:include filename="$(find car_v2_copy1019_description)/urdf/materials.xacro" />
<xacro:include filename="$(find car_v2_copy1019_description)/urdf/car_v2_copy1019.trans" />
<xacro:include filename="$(find car_v2_copy1019_description)/urdf/car_v2_copy1019.gazebo" />
<link name="base_link">
  <inertial>
    <origin xyz="-0.033614332957262155 -0.004539784516663659 0.05035636914443814" rpy="0 0 0"/>
    <mass value="10.997959919526476"/>
    <inertia ixx="0.068393" iyy="0.12963" izz="0.139744" ixy="1.4e-05" iyz="-4e-06" ixz="-0.00959"/>
  </inertial>
  <visual>
    <origin xyz="0 0 0" rpy="0 0 0"/>
    <geometry>
      <mesh filename="package://car_v2_copy1019_description/meshes/base_link.stl" scale="0.001 0.001 0.001"/>
    </geometry>
    <material name="silver"/>
  </visual>
  <collision>
    <origin xyz="0 0 0" rpy="0 0 0"/>
    <geometry>
      <mesh filename="package://car_v2_copy1019_description/meshes/base_link.stl" scale="0.001 0.001 0.001"/>
    </geometry>
  </collision>
</link>

<link name="c2_v1_1">
  <inertial>
    <origin xyz="-1.4567706968504623e-07 -0.015000142754442267 -7.979727989493313e-17" rpy="0 0 0"/>
    <mass value="1.1837521118726337"/>
    <inertia ixx="0.000562" iyy="0.000947" izz="0.000562" ixy="0.0" iyz="0.0" ixz="-0.0"/>
  </inertial>
  <visual>
    <origin xyz="-0.099195 0.122049 -0.0225" rpy="0 0 0"/>
    <geometry>
      <mesh filename="package://car_v2_copy1019_description/meshes/c2_v1_1.stl" scale="0.001 0.001 0.001"/>
    </geometry>
    <material name="silver"/>
  </visual>
  <collision>
    <origin xyz="-0.099195 0.122049 -0.0225" rpy="0 0 0"/>
    <geometry>
      <mesh filename="package://car_v2_copy1019_description/meshes/c2_v1_1.stl" scale="0.001 0.001 0.001"/>
    </geometry>
  </collision>
</link>

<link name="c2_v1__1__1">
  <inertial>
    <origin xyz="-1.4567706967116845e-07 0.014999857245557718 -9.71445146547012e-17" rpy="0 0 0"/>
    <mass value="1.1837521118726337"/>
    <inertia ixx="0.000562" iyy="0.000947" izz="0.000562" ixy="-0.0" iyz="-0.0" ixz="0.0"/>
  </inertial>
  <visual>
    <origin xyz="-0.099195 -0.112951 -0.0225" rpy="0 0 0"/>
    <geometry>
      <mesh filename="package://car_v2_copy1019_description/meshes/c2_v1__1__1.stl" scale="0.001 0.001 0.001"/>
    </geometry>
    <material name="silver"/>
  </visual>
  <collision>
    <origin xyz="-0.099195 -0.112951 -0.0225" rpy="0 0 0"/>
    <geometry>
      <mesh filename="package://car_v2_copy1019_description/meshes/c2_v1__1__1.stl" scale="0.001 0.001 0.001"/>
    </geometry>
  </collision>
</link>

<link name="lidar_v1_1">
  <inertial>
    <origin xyz="-1.4668289803621004e-07 -1.427544422272914e-07 0.00985849993873536" rpy="0 0 0"/>
    <mass value="0.5286905929941373"/>
    <inertia ixx="0.000159" iyy="0.000159" izz="0.000284" ixy="-0.0" iyz="-0.0" ixz="-0.0"/>
  </inertial>
  <visual>
    <origin xyz="0.070805 0.004549 -0.165" rpy="0 0 0"/>
    <geometry>
      <mesh filename="package://car_v2_copy1019_description/meshes/lidar_v1_1.stl" scale="0.001 0.001 0.001"/>
    </geometry>
    <material name="silver"/>
  </visual>
  <collision>
    <origin xyz="0.070805 0.004549 -0.165" rpy="0 0 0"/>
    <geometry>
      <mesh filename="package://car_v2_copy1019_description/meshes/lidar_v1_1.stl" scale="0.001 0.001 0.001"/>
    </geometry>
  </collision>
</link>

<joint name="Revolute 1" type="continuous">
  <origin xyz="0.099195 -0.122049 0.0225" rpy="0 0 0"/>
  <parent link="base_link"/>
  <child link="c2_v1_1"/>
  <axis xyz="0.0 -1.0 0.0"/>
</joint>

<joint name="Revolute 2" type="continuous">
  <origin xyz="0.099195 0.112951 0.0225" rpy="0 0 0"/>
  <parent link="base_link"/>
  <child link="c2_v1__1__1"/>
  <axis xyz="0.0 1.0 -0.0"/>
</joint>

<joint name="Rigid 3" type="fixed">
  <origin xyz="-0.070805 -0.004549 0.165" rpy="0 0 0"/>
  <parent link="base_link"/>
  <child link="lidar_v1_1"/>
</joint>

</robot>
