<?xml version="1.0" ?>
<!-- =================================================================================== -->
<!-- |    This document was autogenerated by xacro from urdf\fourWheelCar.xacro        | -->
<!-- |    EDITING THIS FILE BY HAND IS NOT RECOMMENDED                                 | -->
<!-- =================================================================================== -->
<robot xmlns:xacro="http://www.ros.org/wiki/xacro" name="fourWheelCar">
  <material name="silver">
    <color rgba="0.700 0.700 0.700 1.000"/>
  </material>
  <transmission name="Revolute 1_tran">
    <type>transmission_interface/SimpleTransmission</type>
    <joint name="Revolute 1">
      <hardwareInterface>hardware_interface/EffortJointInterface</hardwareInterface>
    </joint>
    <actuator name="Revolute 1_actr">
      <hardwareInterface>hardware_interface/EffortJointInterface</hardwareInterface>
      <mechanicalReduction>1</mechanicalReduction>
    </actuator>
  </transmission>
  <transmission name="Revolute 2_tran">
    <type>transmission_interface/SimpleTransmission</type>
    <joint name="Revolute 2">
      <hardwareInterface>hardware_interface/EffortJointInterface</hardwareInterface>
    </joint>
    <actuator name="Revolute 2_actr">
      <hardwareInterface>hardware_interface/EffortJointInterface</hardwareInterface>
      <mechanicalReduction>1</mechanicalReduction>
    </actuator>
  </transmission>
  <transmission name="Revolute 3_tran">
    <type>transmission_interface/SimpleTransmission</type>
    <joint name="Revolute 3">
      <hardwareInterface>hardware_interface/EffortJointInterface</hardwareInterface>
    </joint>
    <actuator name="Revolute 3_actr">
      <hardwareInterface>hardware_interface/EffortJointInterface</hardwareInterface>
      <mechanicalReduction>1</mechanicalReduction>
    </actuator>
  </transmission>
  <transmission name="Revolute 4_tran">
    <type>transmission_interface/SimpleTransmission</type>
    <joint name="Revolute 4">
      <hardwareInterface>hardware_interface/EffortJointInterface</hardwareInterface>
    </joint>
    <actuator name="Revolute 4_actr">
      <hardwareInterface>hardware_interface/EffortJointInterface</hardwareInterface>
      <mechanicalReduction>1</mechanicalReduction>
    </actuator>
  </transmission>
  <gazebo>
    <plugin name="control" filename="libgazebo_ros_control.so"/>
  </gazebo>
  <gazebo reference="base_link">
    <material>Gazebo/Silver</material>
    <mu1>0.2</mu1>
    <mu2>0.2</mu2>
    <selfCollide>true</selfCollide>
    <gravity>true</gravity>
  </gazebo>
  <gazebo reference="wheel_v1_1">
    <material>Gazebo/Silver</material>
    <mu1>0.2</mu1>
    <mu2>0.2</mu2>
    <selfCollide>true</selfCollide>
  </gazebo>
  <gazebo reference="wheel_v1__1__1">
    <material>Gazebo/Silver</material>
    <mu1>0.2</mu1>
    <mu2>0.2</mu2>
    <selfCollide>true</selfCollide>
  </gazebo>
  <gazebo reference="wheel_v1__2__1">
    <material>Gazebo/Silver</material>
    <mu1>0.2</mu1>
    <mu2>0.2</mu2>
    <selfCollide>true</selfCollide>
  </gazebo>
  <gazebo reference="wheel_v1__3__1">
    <material>Gazebo/Silver</material>
    <mu1>0.2</mu1>
    <mu2>0.2</mu2>
    <selfCollide>true</selfCollide>
  </gazebo>
  <gazebo reference="lidar_v1_1">
    <material>Gazebo/Silver</material>
    <mu1>0.2</mu1>
    <mu2>0.2</mu2>
    <selfCollide>true</selfCollide>
  </gazebo>
  <link name="base_link">
    <inertial>
      <origin xyz="-0.031141049832366353 9.242377183248719e-06 0.050011490590469526" rpy="0 0 0"/>
      <mass value="11.13582814957309"/>
      <inertia ixx="0.069638" iyy="0.130358" izz="0.141493" ixy="1.4e-05" iyz="-4e-06" ixz="-0.009844"/>
    </inertial>
    <visual>
      <origin xyz="0 0 0" rpy="0 0 0"/>
      <geometry>
        <mesh filename="package://fourWheelCar_description/meshes/base_link.stl" scale="0.001 0.001 0.001"/>
      </geometry>
      <material name="silver"/>
    </visual>
    <collision>
      <origin xyz="0 0 0" rpy="0 0 0"/>
      <geometry>
        <mesh filename="package://fourWheelCar_description/meshes/base_link.stl" scale="0.001 0.001 0.001"/>
      </geometry>
    </collision>
  </link>
  <link name="wheel_v1_1">
    <inertial>
      <origin xyz="-1.3877787807814457e-17 -0.015000000000000041 0.0" rpy="0 0 0"/>
      <mass value="1.1837521118726337"/>
      <inertia ixx="0.000562" iyy="0.000947" izz="0.000562" ixy="-0.0" iyz="-0.0" ixz="-0.0"/>
    </inertial>
    <visual>
      <origin xyz="-0.1025 0.1175 -0.0225" rpy="0 0 0"/>
      <geometry>
        <mesh filename="package://fourWheelCar_description/meshes/wheel_v1_1.stl" scale="0.001 0.001 0.001"/>
      </geometry>
      <material name="silver"/>
    </visual>
    <collision>
      <origin xyz="-0.1025 0.1175 -0.0225" rpy="0 0 0"/>
      <geometry>
        <mesh filename="package://fourWheelCar_description/meshes/wheel_v1_1.stl" scale="0.001 0.001 0.001"/>
      </geometry>
    </collision>
  </link>
  <link name="wheel_v1__1__1">
    <inertial>
      <origin xyz="-1.3877787807814457e-17 0.014999999999999958 0.0" rpy="0 0 0"/>
      <mass value="1.1837521118726337"/>
      <inertia ixx="0.000562" iyy="0.000947" izz="0.000562" ixy="0.0" iyz="-0.0" ixz="0.0"/>
    </inertial>
    <visual>
      <origin xyz="-0.1025 -0.1175 -0.0225" rpy="0 0 0"/>
      <geometry>
        <mesh filename="package://fourWheelCar_description/meshes/wheel_v1__1__1.stl" scale="0.001 0.001 0.001"/>
      </geometry>
      <material name="silver"/>
    </visual>
    <collision>
      <origin xyz="-0.1025 -0.1175 -0.0225" rpy="0 0 0"/>
      <geometry>
        <mesh filename="package://fourWheelCar_description/meshes/wheel_v1__1__1.stl" scale="0.001 0.001 0.001"/>
      </geometry>
    </collision>
  </link>
  <link name="wheel_v1__2__1">
    <inertial>
      <origin xyz="-1.3877787807814457e-17 -0.015000000000000041 3.122502256758253e-17" rpy="0 0 0"/>
      <mass value="1.1837521118726337"/>
      <inertia ixx="0.000562" iyy="0.000947" izz="0.000562" ixy="0.0" iyz="0.0" ixz="-0.0"/>
    </inertial>
    <visual>
      <origin xyz="0.0975 0.1175 -0.0225" rpy="0 0 0"/>
      <geometry>
        <mesh filename="package://fourWheelCar_description/meshes/wheel_v1__2__1.stl" scale="0.001 0.001 0.001"/>
      </geometry>
      <material name="silver"/>
    </visual>
    <collision>
      <origin xyz="0.0975 0.1175 -0.0225" rpy="0 0 0"/>
      <geometry>
        <mesh filename="package://fourWheelCar_description/meshes/wheel_v1__2__1.stl" scale="0.001 0.001 0.001"/>
      </geometry>
    </collision>
  </link>
  <link name="wheel_v1__3__1">
    <inertial>
      <origin xyz="-1.3877787807814457e-17 0.014999999999999958 3.469446951953614e-17" rpy="0 0 0"/>
      <mass value="1.1837521118726337"/>
      <inertia ixx="0.000562" iyy="0.000947" izz="0.000562" ixy="0.0" iyz="-0.0" ixz="0.0"/>
    </inertial>
    <visual>
      <origin xyz="0.0975 -0.1175 -0.0225" rpy="0 0 0"/>
      <geometry>
        <mesh filename="package://fourWheelCar_description/meshes/wheel_v1__3__1.stl" scale="0.001 0.001 0.001"/>
      </geometry>
      <material name="silver"/>
    </visual>
    <collision>
      <origin xyz="0.0975 -0.1175 -0.0225" rpy="0 0 0"/>
      <geometry>
        <mesh filename="package://fourWheelCar_description/meshes/wheel_v1__3__1.stl" scale="0.001 0.001 0.001"/>
      </geometry>
    </collision>
  </link>
  <link name="lidar_v1_1">
    <inertial>
      <origin xyz="-1.0058283789193823e-09 0.0 0.009858499938735416" rpy="0 0 0"/>
      <mass value="0.5286905929941373"/>
      <inertia ixx="0.000159" iyy="0.000159" izz="0.000284" ixy="-0.0" iyz="-0.0" ixz="0.0"/>
    </inertial>
    <visual>
      <origin xyz="0.0675 -0.0 -0.165" rpy="0 0 0"/>
      <geometry>
        <mesh filename="package://fourWheelCar_description/meshes/lidar_v1_1.stl" scale="0.001 0.001 0.001"/>
      </geometry>
      <material name="silver"/>
    </visual>
    <collision>
      <origin xyz="0.0675 -0.0 -0.165" rpy="0 0 0"/>
      <geometry>
        <mesh filename="package://fourWheelCar_description/meshes/lidar_v1_1.stl" scale="0.001 0.001 0.001"/>
      </geometry>
    </collision>
  </link>
  <joint name="Revolute 1" type="continuous">
    <origin xyz="0.1025 -0.1175 0.0225" rpy="0 0 0"/>
    <parent link="base_link"/>
    <child link="wheel_v1_1"/>
    <axis xyz="0.0 -1.0 0.0"/>
  </joint>
  <joint name="Revolute 2" type="continuous">
    <origin xyz="0.1025 0.1175 0.0225" rpy="0 0 0"/>
    <parent link="base_link"/>
    <child link="wheel_v1__1__1"/>
    <axis xyz="0.0 1.0 0.0"/>
  </joint>
  <joint name="Revolute 3" type="continuous">
    <origin xyz="-0.0975 -0.1175 0.0225" rpy="0 0 0"/>
    <parent link="base_link"/>
    <child link="wheel_v1__2__1"/>
    <axis xyz="0.0 -1.0 0.0"/>
  </joint>
  <joint name="Revolute 4" type="continuous">
    <origin xyz="-0.0975 0.1175 0.0225" rpy="0 0 0"/>
    <parent link="base_link"/>
    <child link="wheel_v1__3__1"/>
    <axis xyz="0.0 1.0 0.0"/>
  </joint>
  <joint name="Rigid 5" type="fixed">
    <origin xyz="-0.0675 0.0 0.165" rpy="0 0 0"/>
    <parent link="base_link"/>
    <child link="lidar_v1_1"/>
  </joint>
</robot>
