<?xml version="1.0" ?>
<robot name="car_copy_2" xmlns:xacro="http://www.ros.org/wiki/xacro">

<xacro:include filename="$(find car_copy_2_description)/urdf/materials.xacro" />
<xacro:include filename="$(find car_copy_2_description)/urdf/car_copy_2.trans" />
<xacro:include filename="$(find car_copy_2_description)/urdf/car_copy_2.gazebo" />
<link name="base_link">
  <inertial>
    <origin xyz="-0.05744576591784277 0.026263063131666993 0.03490782751752176" rpy="0 0 0"/>
    <mass value="11.13582814957309"/>
    <inertia ixx="0.069638" iyy="0.130555" izz="0.141689" ixy="1.4e-05" iyz="-4e-06" ixz="-0.009882"/>
  </inertial>
  <visual>
    <origin xyz="0 0 0" rpy="0 0 0"/>
    <geometry>
      <mesh filename="package://car_copy_2_description/meshes/base_link.stl" scale="0.001 0.001 0.001"/>
    </geometry>
    <material name="silver"/>
  </visual>
  <collision>
    <origin xyz="0 0 0" rpy="0 0 0"/>
    <geometry>
      <mesh filename="package://car_copy_2_description/meshes/base_link.stl" scale="0.001 0.001 0.001"/>
    </geometry>
  </collision>
</link>

<link name="lidar_v1_1">
  <inertial>
    <origin xyz="8.890515529325071e-08 -1.7924551614853512e-07 0.009858836865787673" rpy="0 0 0"/>
    <mass value="0.5286905929941373"/>
    <inertia ixx="0.000159" iyy="0.000159" izz="0.000284" ixy="-0.0" iyz="0.0" ixz="0.0"/>
  </inertial>
  <visual>
    <origin xyz="0.093681 -0.026254 -0.149896" rpy="0 0 0"/>
    <geometry>
      <mesh filename="package://car_copy_2_description/meshes/lidar_v1_1.stl" scale="0.001 0.001 0.001"/>
    </geometry>
    <material name="silver"/>
  </visual>
  <collision>
    <origin xyz="0.093681 -0.026254 -0.149896" rpy="0 0 0"/>
    <geometry>
      <mesh filename="package://car_copy_2_description/meshes/lidar_v1_1.stl" scale="0.001 0.001 0.001"/>
    </geometry>
  </collision>
</link>

<link name="macWheel_big_v2_1">
  <inertial>
    <origin xyz="8.991099481603371e-08 -0.021494204245300533 3.369220982320578e-07" rpy="0 0 0"/>
    <mass value="0.4755858352821359"/>
    <inertia ixx="0.000195" iyy="0.000201" izz="0.000195" ixy="-0.0" iyz="-0.0" ixz="0.0"/>
  </inertial>
  <visual>
    <origin xyz="-0.076319 0.091246 -0.007396" rpy="0 0 0"/>
    <geometry>
      <mesh filename="package://car_copy_2_description/meshes/macWheel_big_v2_1.stl" scale="0.001 0.001 0.001"/>
    </geometry>
    <material name="silver"/>
  </visual>
  <collision>
    <origin xyz="-0.076319 0.091246 -0.007396" rpy="0 0 0"/>
    <geometry>
      <mesh filename="package://car_copy_2_description/meshes/macWheel_big_v2_1.stl" scale="0.001 0.001 0.001"/>
    </geometry>
  </collision>
</link>

<link name="wheel_small_com_big_v1_1">
  <inertial>
    <origin xyz="-4.1545169586487685e-07 -4.159208721876695e-07 3.1900678559501627e-07" rpy="0 0 0"/>
    <mass value="0.05173563165158379"/>
    <inertia ixx="5e-06" iyy="4e-06" izz="5e-06" ixy="-2e-06" iyz="2e-06" ixz="1e-06"/>
  </inertial>
  <visual>
    <origin xyz="-0.098525 0.112755 -0.02958" rpy="0 0 0"/>
    <geometry>
      <mesh filename="package://car_copy_2_description/meshes/wheel_small_com_big_v1_1.stl" scale="0.001 0.001 0.001"/>
    </geometry>
    <material name="silver"/>
  </visual>
  <collision>
    <origin xyz="-0.098525 0.112755 -0.02958" rpy="0 0 0"/>
    <geometry>
      <mesh filename="package://car_copy_2_description/meshes/wheel_small_com_big_v1_1.stl" scale="0.001 0.001 0.001"/>
    </geometry>
  </collision>
</link>

<link name="wheel_small_com_big_v1__1__1">
  <inertial>
    <origin xyz="3.015862848620987e-07 -4.159208233378564e-07 4.3692696691244315e-07" rpy="0 0 0"/>
    <mass value="0.05173563165158379"/>
    <inertia ixx="4e-06" iyy="4e-06" izz="6e-06" ixy="-2e-06" iyz="-0.0" ixz="-0.0"/>
  </inertial>
  <visual>
    <origin xyz="-0.076334 0.112755 -0.038784" rpy="0 0 0"/>
    <geometry>
      <mesh filename="package://car_copy_2_description/meshes/wheel_small_com_big_v1__1__1.stl" scale="0.001 0.001 0.001"/>
    </geometry>
    <material name="silver"/>
  </visual>
  <collision>
    <origin xyz="-0.076334 0.112755 -0.038784" rpy="0 0 0"/>
    <geometry>
      <mesh filename="package://car_copy_2_description/meshes/wheel_small_com_big_v1__1__1.stl" scale="0.001 0.001 0.001"/>
    </geometry>
  </collision>
</link>

<link name="wheel_small_com_big_v1__2__1">
  <inertial>
    <origin xyz="-4.0472634010857433e-07 7.429832887817511e-09 3.190067821672027e-07" rpy="0 0 0"/>
    <mass value="0.05173563165158379"/>
    <inertia ixx="5e-06" iyy="4e-06" izz="5e-06" ixy="-2e-06" iyz="-2e-06" ixz="-1e-06"/>
  </inertial>
  <visual>
    <origin xyz="-0.054114 0.112725 -0.02958" rpy="0 0 0"/>
    <geometry>
      <mesh filename="package://car_copy_2_description/meshes/wheel_small_com_big_v1__2__1.stl" scale="0.001 0.001 0.001"/>
    </geometry>
    <material name="silver"/>
  </visual>
  <collision>
    <origin xyz="-0.054114 0.112725 -0.02958" rpy="0 0 0"/>
    <geometry>
      <mesh filename="package://car_copy_2_description/meshes/wheel_small_com_big_v1__2__1.stl" scale="0.001 0.001 0.001"/>
    </geometry>
  </collision>
</link>

<link name="wheel_small_com_big_v1__3__1">
  <inertial>
    <origin xyz="-1.0088931273743995e-08 7.429783607793006e-09 1.252517464137709e-07" rpy="0 0 0"/>
    <mass value="0.05173563165158379"/>
    <inertia ixx="6e-06" iyy="4e-06" izz="4e-06" ixy="0.0" iyz="-2e-06" ixz="0.0"/>
  </inertial>
  <visual>
    <origin xyz="-0.044931 0.112725 -0.007381" rpy="0 0 0"/>
    <geometry>
      <mesh filename="package://car_copy_2_description/meshes/wheel_small_com_big_v1__3__1.stl" scale="0.001 0.001 0.001"/>
    </geometry>
    <material name="silver"/>
  </visual>
  <collision>
    <origin xyz="-0.044931 0.112725 -0.007381" rpy="0 0 0"/>
    <geometry>
      <mesh filename="package://car_copy_2_description/meshes/wheel_small_com_big_v1__3__1.stl" scale="0.001 0.001 0.001"/>
    </geometry>
  </collision>
</link>

<link name="wheel_small_com_big_v1__4__1">
  <inertial>
    <origin xyz="1.8991089797970595e-07 7.429785620072238e-09 -4.5139764098638124e-07" rpy="0 0 0"/>
    <mass value="0.05173563165158379"/>
    <inertia ixx="6e-06" iyy="4e-06" izz="4e-06" ixy="-0.0" iyz="2e-06" ixz="0.0"/>
  </inertial>
  <visual>
    <origin xyz="-0.107707 0.112725 -0.007412" rpy="0 0 0"/>
    <geometry>
      <mesh filename="package://car_copy_2_description/meshes/wheel_small_com_big_v1__4__1.stl" scale="0.001 0.001 0.001"/>
    </geometry>
    <material name="silver"/>
  </visual>
  <collision>
    <origin xyz="-0.107707 0.112725 -0.007412" rpy="0 0 0"/>
    <geometry>
      <mesh filename="package://car_copy_2_description/meshes/wheel_small_com_big_v1__4__1.stl" scale="0.001 0.001 0.001"/>
    </geometry>
  </collision>
</link>

<link name="wheel_small_com_big_v1__5__1">
  <inertial>
    <origin xyz="-4.154516963644772e-07 7.429741641362675e-09 3.548471798949654e-07" rpy="0 0 0"/>
    <mass value="0.05173563165158379"/>
    <inertia ixx="5e-06" iyy="4e-06" izz="5e-06" ixy="2e-06" iyz="2e-06" ixz="-1e-06"/>
  </inertial>
  <visual>
    <origin xyz="-0.098525 0.112725 0.014788" rpy="0 0 0"/>
    <geometry>
      <mesh filename="package://car_copy_2_description/meshes/wheel_small_com_big_v1__5__1.stl" scale="0.001 0.001 0.001"/>
    </geometry>
    <material name="silver"/>
  </visual>
  <collision>
    <origin xyz="-0.098525 0.112725 0.014788" rpy="0 0 0"/>
    <geometry>
      <mesh filename="package://car_copy_2_description/meshes/wheel_small_com_big_v1__5__1.stl" scale="0.001 0.001 0.001"/>
    </geometry>
  </collision>
</link>

<link name="wheel_small_com_big_v1__7__1">
  <inertial>
    <origin xyz="3.0158628457066516e-07 7.429790366275668e-09 2.3692696700036708e-07" rpy="0 0 0"/>
    <mass value="0.05173563165158379"/>
    <inertia ixx="4e-06" iyy="4e-06" izz="6e-06" ixy="2e-06" iyz="0.0" ixz="-0.0"/>
  </inertial>
  <visual>
    <origin xyz="-0.076334 0.112725 0.023992" rpy="0 0 0"/>
    <geometry>
      <mesh filename="package://car_copy_2_description/meshes/wheel_small_com_big_v1__7__1.stl" scale="0.001 0.001 0.001"/>
    </geometry>
    <material name="silver"/>
  </visual>
  <collision>
    <origin xyz="-0.076334 0.112725 0.023992" rpy="0 0 0"/>
    <geometry>
      <mesh filename="package://car_copy_2_description/meshes/wheel_small_com_big_v1__7__1.stl" scale="0.001 0.001 0.001"/>
    </geometry>
  </collision>
</link>

<link name="wheel_small_com_big_v1__6__1">
  <inertial>
    <origin xyz="1.0783118038065753e-07 7.429838771999542e-09 -1.5771033719594318e-07" rpy="0 0 0"/>
    <mass value="0.05173563165158379"/>
    <inertia ixx="5e-06" iyy="4e-06" izz="5e-06" ixy="2e-06" iyz="-2e-06" ixz="1e-06"/>
  </inertial>
  <visual>
    <origin xyz="-0.054135 0.112725 0.014809" rpy="0 0 0"/>
    <geometry>
      <mesh filename="package://car_copy_2_description/meshes/wheel_small_com_big_v1__6__1.stl" scale="0.001 0.001 0.001"/>
    </geometry>
    <material name="silver"/>
  </visual>
  <collision>
    <origin xyz="-0.054135 0.112725 0.014809" rpy="0 0 0"/>
    <geometry>
      <mesh filename="package://car_copy_2_description/meshes/wheel_small_com_big_v1__6__1.stl" scale="0.001 0.001 0.001"/>
    </geometry>
  </collision>
</link>

<link name="macWheel_big_v2_Mirror__1">
  <inertial>
    <origin xyz="8.991099474664477e-08 0.02327117826473324 3.369220980290952e-07" rpy="0 0 0"/>
    <mass value="0.4755858352821358"/>
    <inertia ixx="0.000195" iyy="0.000201" izz="0.000195" ixy="0.0" iyz="0.0" ixz="0.0"/>
  </inertial>
  <visual>
    <origin xyz="-0.076319 -0.143754 -0.007396" rpy="0 0 0"/>
    <geometry>
      <mesh filename="package://car_copy_2_description/meshes/macWheel_big_v2_Mirror__1.stl" scale="0.001 0.001 0.001"/>
    </geometry>
    <material name="silver"/>
  </visual>
  <collision>
    <origin xyz="-0.076319 -0.143754 -0.007396" rpy="0 0 0"/>
    <geometry>
      <mesh filename="package://car_copy_2_description/meshes/macWheel_big_v2_Mirror__1.stl" scale="0.001 0.001 0.001"/>
    </geometry>
  </collision>
</link>

<link name="wheel_small_com_big_v1__8__1">
  <inertial>
    <origin xyz="7.199078254360725e-08 -3.34103028021282e-08 -1.6843569376756573e-07" rpy="0 0 0"/>
    <mass value="0.05173563165158379"/>
    <inertia ixx="5e-06" iyy="4e-06" izz="5e-06" ixy="2e-06" iyz="-2e-06" ixz="1e-06"/>
  </inertial>
  <visual>
    <origin xyz="-0.098503 -0.16701 -0.029602" rpy="0 0 0"/>
    <geometry>
      <mesh filename="package://car_copy_2_description/meshes/wheel_small_com_big_v1__8__1.stl" scale="0.001 0.001 0.001"/>
    </geometry>
    <material name="silver"/>
  </visual>
  <collision>
    <origin xyz="-0.098503 -0.16701 -0.029602" rpy="0 0 0"/>
    <geometry>
      <mesh filename="package://car_copy_2_description/meshes/wheel_small_com_big_v1__8__1.stl" scale="0.001 0.001 0.001"/>
    </geometry>
  </collision>
</link>

<link name="wheel_small_com_big_v1__9__1">
  <inertial>
    <origin xyz="3.015862843069872e-07 3.899402557516751e-07 4.3692696678754306e-07" rpy="0 0 0"/>
    <mass value="0.05173563165158379"/>
    <inertia ixx="4e-06" iyy="4e-06" izz="6e-06" ixy="2e-06" iyz="0.0" ixz="-0.0"/>
  </inertial>
  <visual>
    <origin xyz="-0.076334 -0.16704 -0.038784" rpy="0 0 0"/>
    <geometry>
      <mesh filename="package://car_copy_2_description/meshes/wheel_small_com_big_v1__9__1.stl" scale="0.001 0.001 0.001"/>
    </geometry>
    <material name="silver"/>
  </visual>
  <collision>
    <origin xyz="-0.076334 -0.16704 -0.038784" rpy="0 0 0"/>
    <geometry>
      <mesh filename="package://car_copy_2_description/meshes/wheel_small_com_big_v1__9__1.stl" scale="0.001 0.001 0.001"/>
    </geometry>
  </collision>
</link>

<link name="wheel_small_com_big_v1__10__1">
  <inertial>
    <origin xyz="1.0783117992269053e-07 3.899402070406399e-07 -1.6843569693864024e-07" rpy="0 0 0"/>
    <mass value="0.05173563165158379"/>
    <inertia ixx="5e-06" iyy="4e-06" izz="5e-06" ixy="2e-06" iyz="2e-06" ixz="-1e-06"/>
  </inertial>
  <visual>
    <origin xyz="-0.054135 -0.16704 -0.029602" rpy="0 0 0"/>
    <geometry>
      <mesh filename="package://car_copy_2_description/meshes/wheel_small_com_big_v1__10__1.stl" scale="0.001 0.001 0.001"/>
    </geometry>
    <material name="silver"/>
  </visual>
  <collision>
    <origin xyz="-0.054135 -0.16704 -0.029602" rpy="0 0 0"/>
    <geometry>
      <mesh filename="package://car_copy_2_description/meshes/wheel_small_com_big_v1__10__1.stl" scale="0.001 0.001 0.001"/>
    </geometry>
  </collision>
</link>

<link name="wheel_small_com_big_v1__11__1">
  <inertial>
    <origin xyz="-1.0088932335394762e-08 -3.3410351013563044e-08 1.2525174600003935e-07" rpy="0 0 0"/>
    <mass value="0.05173563165158379"/>
    <inertia ixx="6e-06" iyy="4e-06" izz="4e-06" ixy="-0.0" iyz="2e-06" ixz="0.0"/>
  </inertial>
  <visual>
    <origin xyz="-0.044931 -0.16701 -0.007381" rpy="0 0 0"/>
    <geometry>
      <mesh filename="package://car_copy_2_description/meshes/wheel_small_com_big_v1__11__1.stl" scale="0.001 0.001 0.001"/>
    </geometry>
    <material name="silver"/>
  </visual>
  <collision>
    <origin xyz="-0.044931 -0.16701 -0.007381" rpy="0 0 0"/>
    <geometry>
      <mesh filename="package://car_copy_2_description/meshes/wheel_small_com_big_v1__11__1.stl" scale="0.001 0.001 0.001"/>
    </geometry>
  </collision>
</link>

<link name="wheel_small_com_big_v1__12__1">
  <inertial>
    <origin xyz="1.8991106845445138e-07 3.8994024945115946e-07 1.2525174589855803e-07" rpy="0 0 0"/>
    <mass value="0.05173563165158379"/>
    <inertia ixx="6e-06" iyy="4e-06" izz="4e-06" ixy="0.0" iyz="-2e-06" ixz="0.0"/>
  </inertial>
  <visual>
    <origin xyz="-0.107707 -0.16704 -0.007381" rpy="0 0 0"/>
    <geometry>
      <mesh filename="package://car_copy_2_description/meshes/wheel_small_com_big_v1__12__1.stl" scale="0.001 0.001 0.001"/>
    </geometry>
    <material name="silver"/>
  </visual>
  <collision>
    <origin xyz="-0.107707 -0.16704 -0.007381" rpy="0 0 0"/>
    <geometry>
      <mesh filename="package://car_copy_2_description/meshes/wheel_small_com_big_v1__12__1.stl" scale="0.001 0.001 0.001"/>
    </geometry>
  </collision>
</link>

<link name="wheel_small_com_big_v1__13__1">
  <inertial>
    <origin xyz="1.0783118069290776e-07 -3.3410405525513553e-08 -1.577103363840926e-07" rpy="0 0 0"/>
    <mass value="0.05173563165158379"/>
    <inertia ixx="5e-06" iyy="4e-06" izz="5e-06" ixy="-2e-06" iyz="2e-06" ixz="1e-06"/>
  </inertial>
  <visual>
    <origin xyz="-0.054135 -0.16701 0.014809" rpy="0 0 0"/>
    <geometry>
      <mesh filename="package://car_copy_2_description/meshes/wheel_small_com_big_v1__13__1.stl" scale="0.001 0.001 0.001"/>
    </geometry>
    <material name="silver"/>
  </visual>
  <collision>
    <origin xyz="-0.054135 -0.16701 0.014809" rpy="0 0 0"/>
    <geometry>
      <mesh filename="package://car_copy_2_description/meshes/wheel_small_com_big_v1__13__1.stl" scale="0.001 0.001 0.001"/>
    </geometry>
  </collision>
</link>

<link name="wheel_small_com_big_v1__14__1">
  <inertial>
    <origin xyz="3.0158628468168747e-07 -3.3410357730412343e-08 2.3692696789201495e-07" rpy="0 0 0"/>
    <mass value="0.05173563165158379"/>
    <inertia ixx="4e-06" iyy="4e-06" izz="6e-06" ixy="-2e-06" iyz="-0.0" ixz="-0.0"/>
  </inertial>
  <visual>
    <origin xyz="-0.076334 -0.16701 0.023992" rpy="0 0 0"/>
    <geometry>
      <mesh filename="package://car_copy_2_description/meshes/wheel_small_com_big_v1__14__1.stl" scale="0.001 0.001 0.001"/>
    </geometry>
    <material name="silver"/>
  </visual>
  <collision>
    <origin xyz="-0.076334 -0.16701 0.023992" rpy="0 0 0"/>
    <geometry>
      <mesh filename="package://car_copy_2_description/meshes/wheel_small_com_big_v1__14__1.stl" scale="0.001 0.001 0.001"/>
    </geometry>
  </collision>
</link>

<link name="wheel_small_com_big_v1__15__1">
  <inertial>
    <origin xyz="7.199078351505239e-08 3.8994029774586103e-07 -1.5771034077467772e-07" rpy="0 0 0"/>
    <mass value="0.05173563165158379"/>
    <inertia ixx="5e-06" iyy="4e-06" izz="5e-06" ixy="-2e-06" iyz="-2e-06" ixz="-1e-06"/>
  </inertial>
  <visual>
    <origin xyz="-0.098503 -0.16704 0.014809" rpy="0 0 0"/>
    <geometry>
      <mesh filename="package://car_copy_2_description/meshes/wheel_small_com_big_v1__15__1.stl" scale="0.001 0.001 0.001"/>
    </geometry>
    <material name="silver"/>
  </visual>
  <collision>
    <origin xyz="-0.098503 -0.16704 0.014809" rpy="0 0 0"/>
    <geometry>
      <mesh filename="package://car_copy_2_description/meshes/wheel_small_com_big_v1__15__1.stl" scale="0.001 0.001 0.001"/>
    </geometry>
  </collision>
</link>

<link name="macWheel_big_v2__1__1">
  <inertial>
    <origin xyz="8.991099478827813e-08 0.021493845754267993 3.3693200623009095e-07" rpy="0 0 0"/>
    <mass value="0.4755858352821359"/>
    <inertia ixx="0.000195" iyy="0.000201" izz="0.000195" ixy="0.0" iyz="-0.0" ixz="-0.0"/>
  </inertial>
  <visual>
    <origin xyz="0.133681 -0.143754 -0.007396" rpy="0 0 0"/>
    <geometry>
      <mesh filename="package://car_copy_2_description/meshes/macWheel_big_v2__1__1.stl" scale="0.001 0.001 0.001"/>
    </geometry>
    <material name="silver"/>
  </visual>
  <collision>
    <origin xyz="0.133681 -0.143754 -0.007396" rpy="0 0 0"/>
    <geometry>
      <mesh filename="package://car_copy_2_description/meshes/macWheel_big_v2__1__1.stl" scale="0.001 0.001 0.001"/>
    </geometry>
  </collision>
</link>

<link name="wheel_small_com_big_v1__16__1">
  <inertial>
    <origin xyz="-4.1545169618406597e-07 -3.6592087215847613e-07 3.190067861501278e-07" rpy="0 0 0"/>
    <mass value="0.05173563165158379"/>
    <inertia ixx="5e-06" iyy="4e-06" izz="5e-06" ixy="-2e-06" iyz="2e-06" ixz="1e-06"/>
  </inertial>
  <visual>
    <origin xyz="0.111475 -0.165233 -0.02958" rpy="0 0 0"/>
    <geometry>
      <mesh filename="package://car_copy_2_description/meshes/wheel_small_com_big_v1__16__1.stl" scale="0.001 0.001 0.001"/>
    </geometry>
    <material name="silver"/>
  </visual>
  <collision>
    <origin xyz="0.111475 -0.165233 -0.02958" rpy="0 0 0"/>
    <geometry>
      <mesh filename="package://car_copy_2_description/meshes/wheel_small_com_big_v1__16__1.stl" scale="0.001 0.001 0.001"/>
    </geometry>
  </collision>
</link>

<link name="wheel_small_com_big_v1__17__1">
  <inertial>
    <origin xyz="3.0158628472332083e-07 -3.659208228923294e-07 4.369269677867438e-07" rpy="0 0 0"/>
    <mass value="0.05173563165158379"/>
    <inertia ixx="4e-06" iyy="4e-06" izz="6e-06" ixy="-2e-06" iyz="-0.0" ixz="-0.0"/>
  </inertial>
  <visual>
    <origin xyz="0.133666 -0.165233 -0.038784" rpy="0 0 0"/>
    <geometry>
      <mesh filename="package://car_copy_2_description/meshes/wheel_small_com_big_v1__17__1.stl" scale="0.001 0.001 0.001"/>
    </geometry>
    <material name="silver"/>
  </visual>
  <collision>
    <origin xyz="0.133666 -0.165233 -0.038784" rpy="0 0 0"/>
    <geometry>
      <mesh filename="package://car_copy_2_description/meshes/wheel_small_com_big_v1__17__1.stl" scale="0.001 0.001 0.001"/>
    </geometry>
  </collision>
</link>

<link name="wheel_small_com_big_v1__18__1">
  <inertial>
    <origin xyz="1.8991089988096288e-07 5.742978409495336e-08 -4.5139764158919765e-07" rpy="0 0 0"/>
    <mass value="0.05173563165158379"/>
    <inertia ixx="6e-06" iyy="4e-06" izz="4e-06" ixy="-0.0" iyz="2e-06" ixz="0.0"/>
  </inertial>
  <visual>
    <origin xyz="0.102293 -0.165263 -0.007412" rpy="0 0 0"/>
    <geometry>
      <mesh filename="package://car_copy_2_description/meshes/wheel_small_com_big_v1__18__1.stl" scale="0.001 0.001 0.001"/>
    </geometry>
    <material name="silver"/>
  </visual>
  <collision>
    <origin xyz="0.102293 -0.165263 -0.007412" rpy="0 0 0"/>
    <geometry>
      <mesh filename="package://car_copy_2_description/meshes/wheel_small_com_big_v1__18__1.stl" scale="0.001 0.001 0.001"/>
    </geometry>
  </collision>
</link>

<link name="wheel_small_com_big_v1__19__1">
  <inertial>
    <origin xyz="-4.1545169618406597e-07 5.742974157341152e-08 3.548471804726283e-07" rpy="0 0 0"/>
    <mass value="0.05173563165158379"/>
    <inertia ixx="5e-06" iyy="4e-06" izz="5e-06" ixy="2e-06" iyz="2e-06" ixz="-1e-06"/>
  </inertial>
  <visual>
    <origin xyz="0.111475 -0.165263 0.014788" rpy="0 0 0"/>
    <geometry>
      <mesh filename="package://car_copy_2_description/meshes/wheel_small_com_big_v1__19__1.stl" scale="0.001 0.001 0.001"/>
    </geometry>
    <material name="silver"/>
  </visual>
  <collision>
    <origin xyz="0.111475 -0.165263 0.014788" rpy="0 0 0"/>
    <geometry>
      <mesh filename="package://car_copy_2_description/meshes/wheel_small_com_big_v1__19__1.stl" scale="0.001 0.001 0.001"/>
    </geometry>
  </collision>
</link>

<link name="wheel_small_com_big_v1__20__1">
  <inertial>
    <origin xyz="-4.047263396644851e-07 5.742983336110008e-08 3.190067824274112e-07" rpy="0 0 0"/>
    <mass value="0.05173563165158379"/>
    <inertia ixx="5e-06" iyy="4e-06" izz="5e-06" ixy="-2e-06" iyz="-2e-06" ixz="-1e-06"/>
  </inertial>
  <visual>
    <origin xyz="0.155886 -0.165263 -0.02958" rpy="0 0 0"/>
    <geometry>
      <mesh filename="package://car_copy_2_description/meshes/wheel_small_com_big_v1__20__1.stl" scale="0.001 0.001 0.001"/>
    </geometry>
    <material name="silver"/>
  </visual>
  <collision>
    <origin xyz="0.155886 -0.165263 -0.02958" rpy="0 0 0"/>
    <geometry>
      <mesh filename="package://car_copy_2_description/meshes/wheel_small_com_big_v1__20__1.stl" scale="0.001 0.001 0.001"/>
    </geometry>
  </collision>
</link>

<link name="wheel_small_com_big_v1__21__1">
  <inertial>
    <origin xyz="-1.0089100943577733e-08 -3.6592081614772454e-07 -4.5139764168720953e-07" rpy="0 0 0"/>
    <mass value="0.05173563165158379"/>
    <inertia ixx="6e-06" iyy="4e-06" izz="4e-06" ixy="0.0" iyz="-2e-06" ixz="0.0"/>
  </inertial>
  <visual>
    <origin xyz="0.165069 -0.165233 -0.007412" rpy="0 0 0"/>
    <geometry>
      <mesh filename="package://car_copy_2_description/meshes/wheel_small_com_big_v1__21__1.stl" scale="0.001 0.001 0.001"/>
    </geometry>
    <material name="silver"/>
  </visual>
  <collision>
    <origin xyz="0.165069 -0.165233 -0.007412" rpy="0 0 0"/>
    <geometry>
      <mesh filename="package://car_copy_2_description/meshes/wheel_small_com_big_v1__21__1.stl" scale="0.001 0.001 0.001"/>
    </geometry>
  </collision>
</link>

<link name="wheel_small_com_big_v1__22__1">
  <inertial>
    <origin xyz="3.015862846678097e-07 5.7429790589758056e-08 2.3692696787119827e-07" rpy="0 0 0"/>
    <mass value="0.05173563165158379"/>
    <inertia ixx="4e-06" iyy="4e-06" izz="6e-06" ixy="2e-06" iyz="0.0" ixz="-0.0"/>
  </inertial>
  <visual>
    <origin xyz="0.133666 -0.165263 0.023992" rpy="0 0 0"/>
    <geometry>
      <mesh filename="package://car_copy_2_description/meshes/wheel_small_com_big_v1__22__1.stl" scale="0.001 0.001 0.001"/>
    </geometry>
    <material name="silver"/>
  </visual>
  <collision>
    <origin xyz="0.133666 -0.165263 0.023992" rpy="0 0 0"/>
    <geometry>
      <mesh filename="package://car_copy_2_description/meshes/wheel_small_com_big_v1__22__1.stl" scale="0.001 0.001 0.001"/>
    </geometry>
  </collision>
</link>

<link name="wheel_small_com_big_v1__23__1">
  <inertial>
    <origin xyz="3.7429939472866103e-07 -4.1757016064347674e-07 -3.741785504478984e-07" rpy="0 0 0"/>
    <mass value="0.05173563165158379"/>
    <inertia ixx="5e-06" iyy="4e-06" izz="5e-06" ixy="2e-06" iyz="-2e-06" ixz="1e-06"/>
  </inertial>
  <visual>
    <origin xyz="0.154118 -0.166287 0.014509" rpy="0 0 0"/>
    <geometry>
      <mesh filename="package://car_copy_2_description/meshes/wheel_small_com_big_v1__23__1.stl" scale="0.001 0.001 0.001"/>
    </geometry>
    <material name="silver"/>
  </visual>
  <collision>
    <origin xyz="0.154118 -0.166287 0.014509" rpy="0 0 0"/>
    <geometry>
      <mesh filename="package://car_copy_2_description/meshes/wheel_small_com_big_v1__23__1.stl" scale="0.001 0.001 0.001"/>
    </geometry>
  </collision>
</link>

<link name="macWheel_big_v2_Mirror__2">
  <inertial>
    <origin xyz="8.991099476052256e-08 -0.02327153675619756 3.3692209818782237e-07" rpy="0 0 0"/>
    <mass value="0.4755858352821358"/>
    <inertia ixx="0.000195" iyy="0.000201" izz="0.000195" ixy="0.0" iyz="0.0" ixz="0.0"/>
  </inertial>
  <visual>
    <origin xyz="0.133681 0.091246 -0.007396" rpy="0 0 0"/>
    <geometry>
      <mesh filename="package://car_copy_2_description/meshes/macWheel_big_v2_Mirror__2.stl" scale="0.001 0.001 0.001"/>
    </geometry>
    <material name="silver"/>
  </visual>
  <collision>
    <origin xyz="0.133681 0.091246 -0.007396" rpy="0 0 0"/>
    <geometry>
      <mesh filename="package://car_copy_2_description/meshes/macWheel_big_v2_Mirror__2.stl" scale="0.001 0.001 0.001"/>
    </geometry>
  </collision>
</link>

<link name="wheel_small_com_big_v1__31__1">
  <inertial>
    <origin xyz="-1.21764323568474e-07 2.5156871683029713e-07 4.3692696793246055e-07" rpy="0 0 0"/>
    <mass value="0.05173563165158379"/>
    <inertia ixx="4e-06" iyy="4e-06" izz="6e-06" ixy="2e-06" iyz="0.0" ixz="-0.0"/>
  </inertial>
  <visual>
    <origin xyz="0.133696 0.114533 -0.038784" rpy="0 0 0"/>
    <geometry>
      <mesh filename="package://car_copy_2_description/meshes/wheel_small_com_big_v1__31__1.stl" scale="0.001 0.001 0.001"/>
    </geometry>
    <material name="silver"/>
  </visual>
  <collision>
    <origin xyz="0.133696 0.114533 -0.038784" rpy="0 0 0"/>
    <geometry>
      <mesh filename="package://car_copy_2_description/meshes/wheel_small_com_big_v1__31__1.stl" scale="0.001 0.001 0.001"/>
    </geometry>
  </collision>
</link>

<link name="wheel_small_com_big_v1__30__1">
  <inertial>
    <origin xyz="-4.047263403583745e-07 2.5156866959030744e-07 3.1900678305885055e-07" rpy="0 0 0"/>
    <mass value="0.05173563165158379"/>
    <inertia ixx="5e-06" iyy="4e-06" izz="5e-06" ixy="2e-06" iyz="2e-06" ixz="-1e-06"/>
  </inertial>
  <visual>
    <origin xyz="0.155886 0.114533 -0.02958" rpy="0 0 0"/>
    <geometry>
      <mesh filename="package://car_copy_2_description/meshes/wheel_small_com_big_v1__30__1.stl" scale="0.001 0.001 0.001"/>
    </geometry>
    <material name="silver"/>
  </visual>
  <collision>
    <origin xyz="0.155886 0.114533 -0.02958" rpy="0 0 0"/>
    <geometry>
      <mesh filename="package://car_copy_2_description/meshes/wheel_small_com_big_v1__30__1.stl" scale="0.001 0.001 0.001"/>
    </geometry>
  </collision>
</link>

<link name="wheel_small_com_big_v1__29__1">
  <inertial>
    <origin xyz="-4.154516961563104e-07 -3.25080626556451e-07 3.190067862784973e-07" rpy="0 0 0"/>
    <mass value="0.05173563165158379"/>
    <inertia ixx="5e-06" iyy="4e-06" izz="5e-06" ixy="2e-06" iyz="-2e-06" ixz="1e-06"/>
  </inertial>
  <visual>
    <origin xyz="0.111475 0.114502 -0.02958" rpy="0 0 0"/>
    <geometry>
      <mesh filename="package://car_copy_2_description/meshes/wheel_small_com_big_v1__29__1.stl" scale="0.001 0.001 0.001"/>
    </geometry>
    <material name="silver"/>
  </visual>
  <collision>
    <origin xyz="0.111475 0.114502 -0.02958" rpy="0 0 0"/>
    <geometry>
      <mesh filename="package://car_copy_2_description/meshes/wheel_small_com_big_v1__29__1.stl" scale="0.001 0.001 0.001"/>
    </geometry>
  </collision>
</link>

<link name="wheel_small_com_big_v1__28__1">
  <inertial>
    <origin xyz="1.899110684266958e-07 -3.2508068155412406e-07 1.2525174605641787e-07" rpy="0 0 0"/>
    <mass value="0.05173563165158379"/>
    <inertia ixx="6e-06" iyy="4e-06" izz="4e-06" ixy="0.0" iyz="-2e-06" ixz="0.0"/>
  </inertial>
  <visual>
    <origin xyz="0.102293 0.114502 -0.007381" rpy="0 0 0"/>
    <geometry>
      <mesh filename="package://car_copy_2_description/meshes/wheel_small_com_big_v1__28__1.stl" scale="0.001 0.001 0.001"/>
    </geometry>
    <material name="silver"/>
  </visual>
  <collision>
    <origin xyz="0.102293 0.114502 -0.007381" rpy="0 0 0"/>
    <geometry>
      <mesh filename="package://car_copy_2_description/meshes/wheel_small_com_big_v1__28__1.stl" scale="0.001 0.001 0.001"/>
    </geometry>
  </collision>
</link>

<link name="wheel_small_com_big_v1__27__1">
  <inertial>
    <origin xyz="-1.008893213416684e-08 2.515687181348092e-07 1.2525174613448042e-07" rpy="0 0 0"/>
    <mass value="0.05173563165158379"/>
    <inertia ixx="6e-06" iyy="4e-06" izz="4e-06" ixy="-0.0" iyz="2e-06" ixz="0.0"/>
  </inertial>
  <visual>
    <origin xyz="0.165069 0.114533 -0.007381" rpy="0 0 0"/>
    <geometry>
      <mesh filename="package://car_copy_2_description/meshes/wheel_small_com_big_v1__27__1.stl" scale="0.001 0.001 0.001"/>
    </geometry>
    <material name="silver"/>
  </visual>
  <collision>
    <origin xyz="0.165069 0.114533 -0.007381" rpy="0 0 0"/>
    <geometry>
      <mesh filename="package://car_copy_2_description/meshes/wheel_small_com_big_v1__27__1.stl" scale="0.001 0.001 0.001"/>
    </geometry>
  </collision>
</link>

<link name="wheel_small_com_big_v1__26__1">
  <inertial>
    <origin xyz="7.199078354280797e-08 -3.2508063332881143e-07 -1.577103405734498e-07" rpy="0 0 0"/>
    <mass value="0.05173563165158379"/>
    <inertia ixx="5e-06" iyy="4e-06" izz="5e-06" ixy="-2e-06" iyz="-2e-06" ixz="-1e-06"/>
  </inertial>
  <visual>
    <origin xyz="0.111497 0.114502 0.014809" rpy="0 0 0"/>
    <geometry>
      <mesh filename="package://car_copy_2_description/meshes/wheel_small_com_big_v1__26__1.stl" scale="0.001 0.001 0.001"/>
    </geometry>
    <material name="silver"/>
  </visual>
  <collision>
    <origin xyz="0.111497 0.114502 0.014809" rpy="0 0 0"/>
    <geometry>
      <mesh filename="package://car_copy_2_description/meshes/wheel_small_com_big_v1__26__1.stl" scale="0.001 0.001 0.001"/>
    </geometry>
  </collision>
</link>

<link name="wheel_small_com_big_v1__25__1">
  <inertial>
    <origin xyz="-4.0472633897059573e-07 -3.250807301402592e-07 3.5484718438616447e-07" rpy="0 0 0"/>
    <mass value="0.05173563165158379"/>
    <inertia ixx="5e-06" iyy="4e-06" izz="5e-06" ixy="-2e-06" iyz="2e-06" ixz="1e-06"/>
  </inertial>
  <visual>
    <origin xyz="0.155886 0.114502 0.014788" rpy="0 0 0"/>
    <geometry>
      <mesh filename="package://car_copy_2_description/meshes/wheel_small_com_big_v1__25__1.stl" scale="0.001 0.001 0.001"/>
    </geometry>
    <material name="silver"/>
  </visual>
  <collision>
    <origin xyz="0.155886 0.114502 0.014788" rpy="0 0 0"/>
    <geometry>
      <mesh filename="package://car_copy_2_description/meshes/wheel_small_com_big_v1__25__1.stl" scale="0.001 0.001 0.001"/>
    </geometry>
  </collision>
</link>

<link name="wheel_small_com_big_v1__24__1">
  <inertial>
    <origin xyz="-1.2176431712918045e-07 -3.250806760723979e-07 2.3692696809324287e-07" rpy="0 0 0"/>
    <mass value="0.05173563165158379"/>
    <inertia ixx="4e-06" iyy="4e-06" izz="6e-06" ixy="-2e-06" iyz="0.0" ixz="0.0"/>
  </inertial>
  <visual>
    <origin xyz="0.133696 0.114502 0.023992" rpy="0 0 0"/>
    <geometry>
      <mesh filename="package://car_copy_2_description/meshes/wheel_small_com_big_v1__24__1.stl" scale="0.001 0.001 0.001"/>
    </geometry>
    <material name="silver"/>
  </visual>
  <collision>
    <origin xyz="0.133696 0.114502 0.023992" rpy="0 0 0"/>
    <geometry>
      <mesh filename="package://car_copy_2_description/meshes/wheel_small_com_big_v1__24__1.stl" scale="0.001 0.001 0.001"/>
    </geometry>
  </collision>
</link>

<joint name="Rigid 3" type="fixed">
  <origin xyz="-0.093681 0.026254 0.149896" rpy="0 0 0"/>
  <parent link="base_link"/>
  <child link="lidar_v1_1"/>
</joint>

<joint name="Revolute 58" type="continuous">
  <origin xyz="0.076319 -0.091246 0.007396" rpy="0 0 0"/>
  <parent link="base_link"/>
  <child link="macWheel_big_v2_1"/>
  <axis xyz="0.0 -1.0 0.0"/>
</joint>

<joint name="Revolute 59" type="continuous">
  <origin xyz="0.022206 -0.021509 0.022184" rpy="0 0 0"/>
  <parent link="macWheel_big_v2_1"/>
  <child link="wheel_small_com_big_v1_1"/>
  <axis xyz="0.5 0.707107 -0.5"/>
</joint>

<joint name="Revolute 60" type="continuous">
  <origin xyz="1.5e-05 -0.021509 0.031388" rpy="0 0 0"/>
  <parent link="macWheel_big_v2_1"/>
  <child link="wheel_small_com_big_v1__1__1"/>
  <axis xyz="0.707107 0.707107 -0.0"/>
</joint>

<joint name="Revolute 61" type="continuous">
  <origin xyz="-0.022205 -0.021479 0.022184" rpy="0 0 0"/>
  <parent link="macWheel_big_v2_1"/>
  <child link="wheel_small_com_big_v1__2__1"/>
  <axis xyz="-0.5 -0.707107 -0.5"/>
</joint>

<joint name="Revolute 62" type="continuous">
  <origin xyz="-0.031388 -0.021479 -1.5e-05" rpy="0 0 0"/>
  <parent link="macWheel_big_v2_1"/>
  <child link="wheel_small_com_big_v1__3__1"/>
  <axis xyz="-0.0 -0.707107 -0.707107"/>
</joint>

<joint name="Revolute 63" type="continuous">
  <origin xyz="0.031388 -0.021479 1.6e-05" rpy="0 0 0"/>
  <parent link="macWheel_big_v2_1"/>
  <child link="wheel_small_com_big_v1__4__1"/>
  <axis xyz="-0.0 -0.707107 0.707107"/>
</joint>

<joint name="Revolute 64" type="continuous">
  <origin xyz="0.022206 -0.021479 -0.022184" rpy="0 0 0"/>
  <parent link="macWheel_big_v2_1"/>
  <child link="wheel_small_com_big_v1__5__1"/>
  <axis xyz="0.5 -0.707107 0.5"/>
</joint>

<joint name="Revolute 65" type="continuous">
  <origin xyz="1.5e-05 -0.021479 -0.031388" rpy="0 0 0"/>
  <parent link="macWheel_big_v2_1"/>
  <child link="wheel_small_com_big_v1__7__1"/>
  <axis xyz="0.707107 -0.707107 0.0"/>
</joint>

<joint name="Revolute 66" type="continuous">
  <origin xyz="-0.022184 -0.021479 -0.022205" rpy="0 0 0"/>
  <parent link="macWheel_big_v2_1"/>
  <child link="wheel_small_com_big_v1__6__1"/>
  <axis xyz="0.5 -0.707107 -0.5"/>
</joint>

<joint name="Revolute 67" type="continuous">
  <origin xyz="0.076319 0.143754 0.007396" rpy="0 0 0"/>
  <parent link="base_link"/>
  <child link="macWheel_big_v2_Mirror__1"/>
  <axis xyz="0.0 1.0 -0.0"/>
</joint>

<joint name="Revolute 68" type="continuous">
  <origin xyz="0.022184 0.023256 0.022206" rpy="0 0 0"/>
  <parent link="macWheel_big_v2_Mirror__1"/>
  <child link="wheel_small_com_big_v1__8__1"/>
  <axis xyz="-0.5 0.707107 0.5"/>
</joint>

<joint name="Revolute 69" type="continuous">
  <origin xyz="1.5e-05 0.023286 0.031388" rpy="0 0 0"/>
  <parent link="macWheel_big_v2_Mirror__1"/>
  <child link="wheel_small_com_big_v1__9__1"/>
  <axis xyz="-0.707107 0.707107 -0.0"/>
</joint>

<joint name="Revolute 70" type="continuous">
  <origin xyz="-0.022184 0.023286 0.022206" rpy="0 0 0"/>
  <parent link="macWheel_big_v2_Mirror__1"/>
  <child link="wheel_small_com_big_v1__10__1"/>
  <axis xyz="-0.5 0.707107 -0.5"/>
</joint>

<joint name="Revolute 71" type="continuous">
  <origin xyz="-0.031388 0.023256 -1.5e-05" rpy="0 0 0"/>
  <parent link="macWheel_big_v2_Mirror__1"/>
  <child link="wheel_small_com_big_v1__11__1"/>
  <axis xyz="-0.0 0.707107 -0.707107"/>
</joint>

<joint name="Revolute 72" type="continuous">
  <origin xyz="0.031388 0.023286 -1.5e-05" rpy="0 0 0"/>
  <parent link="macWheel_big_v2_Mirror__1"/>
  <child link="wheel_small_com_big_v1__12__1"/>
  <axis xyz="-0.0 -0.707107 -0.707107"/>
</joint>

<joint name="Revolute 73" type="continuous">
  <origin xyz="-0.022184 0.023256 -0.022205" rpy="0 0 0"/>
  <parent link="macWheel_big_v2_Mirror__1"/>
  <child link="wheel_small_com_big_v1__13__1"/>
  <axis xyz="0.5 0.707107 -0.5"/>
</joint>

<joint name="Revolute 74" type="continuous">
  <origin xyz="1.5e-05 0.023256 -0.031388" rpy="0 0 0"/>
  <parent link="macWheel_big_v2_Mirror__1"/>
  <child link="wheel_small_com_big_v1__14__1"/>
  <axis xyz="0.707107 0.707107 -0.0"/>
</joint>

<joint name="Revolute 75" type="continuous">
  <origin xyz="0.022184 0.023286 -0.022205" rpy="0 0 0"/>
  <parent link="macWheel_big_v2_Mirror__1"/>
  <child link="wheel_small_com_big_v1__15__1"/>
  <axis xyz="-0.5 -0.707107 -0.5"/>
</joint>

<joint name="Revolute 76" type="continuous">
  <origin xyz="-0.133681 0.143754 0.007396" rpy="0 0 0"/>
  <parent link="base_link"/>
  <child link="macWheel_big_v2__1__1"/>
  <axis xyz="0.0 1.0 -0.0"/>
</joint>

<joint name="Revolute 77" type="continuous">
  <origin xyz="0.022206 0.021479 0.022184" rpy="0 0 0"/>
  <parent link="macWheel_big_v2__1__1"/>
  <child link="wheel_small_com_big_v1__16__1"/>
  <axis xyz="0.5 0.707107 -0.5"/>
</joint>

<joint name="Revolute 78" type="continuous">
  <origin xyz="1.5e-05 0.021479 0.031388" rpy="0 0 0"/>
  <parent link="macWheel_big_v2__1__1"/>
  <child link="wheel_small_com_big_v1__17__1"/>
  <axis xyz="0.707107 0.707107 -0.0"/>
</joint>

<joint name="Revolute 79" type="continuous">
  <origin xyz="0.031388 0.021509 1.6e-05" rpy="0 0 0"/>
  <parent link="macWheel_big_v2__1__1"/>
  <child link="wheel_small_com_big_v1__18__1"/>
  <axis xyz="-0.0 -0.707107 0.707107"/>
</joint>

<joint name="Revolute 80" type="continuous">
  <origin xyz="0.022206 0.021509 -0.022184" rpy="0 0 0"/>
  <parent link="macWheel_big_v2__1__1"/>
  <child link="wheel_small_com_big_v1__19__1"/>
  <axis xyz="0.5 -0.707107 0.5"/>
</joint>

<joint name="Revolute 81" type="continuous">
  <origin xyz="-0.022205 0.021509 0.022184" rpy="0 0 0"/>
  <parent link="macWheel_big_v2__1__1"/>
  <child link="wheel_small_com_big_v1__20__1"/>
  <axis xyz="0.5 0.707107 0.5"/>
</joint>

<joint name="Revolute 82" type="continuous">
  <origin xyz="-0.031388 0.021479 1.6e-05" rpy="0 0 0"/>
  <parent link="macWheel_big_v2__1__1"/>
  <child link="wheel_small_com_big_v1__21__1"/>
  <axis xyz="-0.0 0.707107 0.707107"/>
</joint>

<joint name="Revolute 83" type="continuous">
  <origin xyz="1.5e-05 0.021509 -0.031388" rpy="0 0 0"/>
  <parent link="macWheel_big_v2__1__1"/>
  <child link="wheel_small_com_big_v1__22__1"/>
  <axis xyz="0.707107 -0.707107 0.0"/>
</joint>

<joint name="Revolute 84" type="continuous">
  <origin xyz="-0.020437 0.022533 -0.021905" rpy="0 0 0"/>
  <parent link="macWheel_big_v2__1__1"/>
  <child link="wheel_small_com_big_v1__23__1"/>
  <axis xyz="0.5 -0.707107 -0.5"/>
</joint>

<joint name="Revolute 85" type="continuous">
  <origin xyz="-0.133681 -0.091246 0.007396" rpy="0 0 0"/>
  <parent link="base_link"/>
  <child link="macWheel_big_v2_Mirror__2"/>
  <axis xyz="0.0 -1.0 0.0"/>
</joint>

<joint name="Revolute 86" type="continuous">
  <origin xyz="-1.5e-05 -0.023287 0.031388" rpy="0 0 0"/>
  <parent link="macWheel_big_v2_Mirror__2"/>
  <child link="wheel_small_com_big_v1__31__1"/>
  <axis xyz="0.707107 -0.707107 0.0"/>
</joint>

<joint name="Revolute 87" type="continuous">
  <origin xyz="-0.022205 -0.023287 0.022184" rpy="0 0 0"/>
  <parent link="macWheel_big_v2_Mirror__2"/>
  <child link="wheel_small_com_big_v1__30__1"/>
  <axis xyz="-0.5 0.707107 -0.5"/>
</joint>

<joint name="Revolute 88" type="continuous">
  <origin xyz="0.022206 -0.023256 0.022184" rpy="0 0 0"/>
  <parent link="macWheel_big_v2_Mirror__2"/>
  <child link="wheel_small_com_big_v1__29__1"/>
  <axis xyz="0.5 -0.707107 -0.5"/>
</joint>

<joint name="Revolute 89" type="continuous">
  <origin xyz="0.031388 -0.023256 -1.5e-05" rpy="0 0 0"/>
  <parent link="macWheel_big_v2_Mirror__2"/>
  <child link="wheel_small_com_big_v1__28__1"/>
  <axis xyz="-0.0 -0.707107 -0.707107"/>
</joint>

<joint name="Revolute 90" type="continuous">
  <origin xyz="-0.031388 -0.023287 -1.5e-05" rpy="0 0 0"/>
  <parent link="macWheel_big_v2_Mirror__2"/>
  <child link="wheel_small_com_big_v1__27__1"/>
  <axis xyz="-0.0 0.707107 -0.707107"/>
</joint>

<joint name="Revolute 91" type="continuous">
  <origin xyz="0.022184 -0.023256 -0.022205" rpy="0 0 0"/>
  <parent link="macWheel_big_v2_Mirror__2"/>
  <child link="wheel_small_com_big_v1__26__1"/>
  <axis xyz="-0.5 -0.707107 -0.5"/>
</joint>

<joint name="Revolute 92" type="continuous">
  <origin xyz="-0.022205 -0.023256 -0.022184" rpy="0 0 0"/>
  <parent link="macWheel_big_v2_Mirror__2"/>
  <child link="wheel_small_com_big_v1__25__1"/>
  <axis xyz="-0.5 -0.707107 0.5"/>
</joint>

<joint name="Revolute 93" type="continuous">
  <origin xyz="-1.5e-05 -0.023256 -0.031388" rpy="0 0 0"/>
  <parent link="macWheel_big_v2_Mirror__2"/>
  <child link="wheel_small_com_big_v1__24__1"/>
  <axis xyz="-0.707107 -0.707107 0.0"/>
</joint>

</robot>
